<mujoco model="ur5e">
  <compiler angle="radian" meshdir="asset_menagerie" inertiagrouprange="0 0" />
  <!-- <compiler angle="radian"
            inertiafromgeom="true"
            meshdir="asset_menagerie"/>
  <option timestep="2e-3"
          iterations="10"
          tolerance="1e-10"
          impratio="20"/> -->
          
  <size nconmax="5000" njmax="5000"/>
  <default>
    <site rgba="0.8 0.6 0.7 0.3" type="ellipsoid" group="3"/>
    <geom contype='1' conaffinity='1' condim='4'  margin="1e-3" solref=".01 1" solimp=".99 .99 .01" />
    <!-- gripper 4-bar linkage -->
    <joint armature="0.05" damping="0.05"/>

    <!-- Visual default class -->
    <default class="visual">
      <geom type="mesh" contype="0" conaffinity="0" group="2"/>
    </default>

    <!-- Collision default class -->
    <default class="collision">
      <geom type="capsule" group="3"/>
      <default class="eef_collision">
        <geom type="cylinder"/>
      </default>
    </default>

    <!-- UR default class -->
    <default class="UR5">
        <joint damping='65'/>
    </default>
    <default class="UR5e">
        <joint damping='45'/>
    </default>
    <default class="GRIPPER">
        <joint damping='5' type="hinge"/>
    </default>
  </default>

  <asset>
    <material name="black" specular="0.5" shininess="0.25" rgba="0.033 0.033 0.033 1"/>
    <material name="jointgray" specular="0.5" shininess="0.25" rgba="0.278 0.278 0.278 1"/>
    <material name="linkgray" specular="0.5" shininess="0.25" rgba="0.82 0.82 0.82 1"/>
    <material name="urblue" specular="0.5" shininess="0.25" rgba="0.49 0.678 0.8 1"/>

    <mesh file="base_0.stl"/>
    <mesh file="base_1.stl"/>
    <mesh file="shoulder_0.stl"/>
    <mesh file="shoulder_1.stl"/>
    <mesh file="shoulder_2.stl"/>
    <mesh file="upperarm_0.stl"/>
    <mesh file="upperarm_1.stl"/>
    <mesh file="upperarm_2.stl"/>
    <mesh file="upperarm_3.stl"/>
    <mesh file="forearm_0.stl"/>
    <mesh file="forearm_1.stl"/>
    <mesh file="forearm_2.stl"/>
    <mesh file="forearm_3.stl"/>
    <mesh file="wrist1_0.stl"/>
    <mesh file="wrist1_1.stl"/>
    <mesh file="wrist1_2.stl"/>
    <mesh file="wrist2_0.stl"/>
    <mesh file="wrist2_1.stl"/>
    <mesh file="wrist2_2.stl"/>
    <mesh file="wrist3.stl"/>

    <mesh name="mount" file="mount.stl" scale="0.0001 0.0001 0.0001" />
    <mesh name="d435" file="d435.stl" scale="0.001 0.001 0.001" />
    <mesh name="ur_rg2_gripper_base_link" file="./gripper_base_link.STL" />
    <mesh name="rg2_gripper_finger1_finger_link" file="./gripper_finger1_finger_link.STL" />
    <mesh name="rg2_gripper_finger1_inner_knuckle_link" file="./gripper_finger1_inner_knuckle_link.STL" />
    <mesh name="rg2_gripper_finger1_finger_tip_link" file="./gripper_finger1_finger_tip_link.STL" />
    <mesh name="rg2_gripper_finger2_finger_link" file="./gripper_finger2_finger_link.STL" />
    <mesh name="rg2_gripper_finger2_inner_knuckle_link" file="./gripper_finger2_inner_knuckle_link.STL" />
    <mesh name="rg2_gripper_finger2_finger_tip_link" file="./gripper_finger2_finger_tip_link.STL" />

    <texture name="bench_tex"   type="2d"       builtin="flat" height="32" width="32" rgb1="0.7 0.7 0.7" />
    <material name="bench_mat"      texture="bench_tex"   shininess="0.1" specular="0.5" reflectance="0.2"/>

  </asset>

  <worldbody>
    <light name="spotlight" mode="targetbodycom" target="wrist_2_link" pos="0 -1 2"/>

    <body name="box_link" pos="0 0 0.395">
        <!-- Robot base table -->
        <geom size=".36 .36 .395" pos ="0 0 0" type="box" material="bench_mat"/>
        <inertial pos="0 0 0" mass="1000" diaginertia="0 0 0" />

        <body name="base" pos="0 0 0.395">
          <inertial mass="4.0" pos="0 0 0" diaginertia="0.00443333156 0.00443333156 0.0072"/>
          <geom mesh="base_0" material="black" class="visual"/>
          <geom mesh="base_1" material="jointgray" class="visual"/>
          <body name="shoulder_link" pos="0 0 0.163">
            <inertial mass="3.7" pos="0 0 0" diaginertia="0.0102675 0.0102675 0.00666"/>
            <joint name="shoulder_pan_joint" class="UR5" axis="0 0 1" limited="true" range="-3.14159 3.14159"/>
            <geom mesh="shoulder_0" material="urblue" class="visual"/>
            <geom mesh="shoulder_1" material="black" class="visual"/>
            <geom mesh="shoulder_2" material="jointgray" class="visual"/>
            <geom class="collision" size="0.06 0.06" pos="0 0 -0.04"/>
            <body name="upper_arm_link" pos="0 0.138 0" quat="1 0 1 0">
              <inertial mass="8.393" pos="0 0 0.2125" diaginertia="0.133886 0.133886 0.0151074"/>
              <joint name="shoulder_lift_joint" class="UR5" axis="0 1 0" limited="true" range="-3.14159 0"/>
              <geom mesh="upperarm_0" material="linkgray" class="visual"/>
              <geom mesh="upperarm_1" material="black" class="visual"/>
              <geom mesh="upperarm_2" material="jointgray" class="visual"/>
              <geom mesh="upperarm_3" material="urblue" class="visual"/>
              <geom class="collision" pos="0 -0.04 0" quat="1 1 0 0" size="0.06 0.06"/>
              <geom class="collision" size="0.05 0.2" pos="0 0 0.2"/>
              <body name="forearm_link" pos="0 -0.131 0.425">
                <inertial mass="2.275" pos="0 0 0.196" diaginertia="0.0311796 0.0311796 0.004095"/>
                <joint name="elbow_joint" class="UR5" axis="0 1 0" limited="true" range="-3.14159 3.14159"/>
                <geom mesh="forearm_0" material="urblue" class="visual"/>
                <geom mesh="forearm_1" material="linkgray" class="visual"/>
                <geom mesh="forearm_2" material="black" class="visual"/>
                <geom mesh="forearm_3" material="jointgray" class="visual"/>
                <geom class="collision" pos="0 0.08 0" quat="1 1 0 0" size="0.055 0.06"/>
                <geom class="collision" size="0.038 0.19" pos="0 0 0.2"/>
                <body name="wrist_1_link" pos="0 0 0.392" quat="1 0 1 0">
                  <inertial mass="1.219" pos="0 0.127 0" diaginertia="0.0025599 0.0025599 0.0021942"/>
                  <joint name="wrist_1_joint" class="UR5e" axis="0 1 0" limited="true" range="-3.14159 3.14159"/>
                  <geom mesh="wrist1_0" material="black" class="visual"/>
                  <geom mesh="wrist1_1" material="urblue" class="visual"/>
                  <geom mesh="wrist1_2" material="jointgray" class="visual"/>
                  <geom class="collision" pos="0 0.05 0" quat="1 1 0 0" size="0.04 0.07"/>
                  <body name="wrist_2_link" pos="0 0.127 0">
                    <inertial mass="1.219" pos="0 0 0.1" diaginertia="0.0025599 0.0025599 0.0021942"/>
                    <joint name="wrist_2_joint" axis="0 0 1" class="UR5e" limited="true" range="-3.14159 3.14159"/>
                    <geom mesh="wrist2_0" material="black" class="visual"/>
                    <geom mesh="wrist2_1" material="urblue" class="visual"/>
                    <geom mesh="wrist2_2" material="jointgray" class="visual"/>
                    <geom class="collision" size="0.04 0.06" pos="0 0 0.04"/>
                    <geom class="collision" pos="0 0.02 0.1" quat="1 1 0 0" size="0.04 0.04"/>
                    <body name="wrist_3_link" pos="0 0 0.1">
                      <inertial mass="0.1889" pos="0 0.0771683 0" quat="1 0 0 1"
                          diaginertia="0.000132134 9.90863e-05 9.90863e-05"/>
                      <joint name="wrist_3_joint" class="UR5e" axis="0 1 0" limited="true" range="-3.14159 3.14159"/>
                      <geom material="linkgray" mesh="wrist3" class="visual"/>
                      <geom class="eef_collision" pos="0 0.08 0" quat="1 1 0 0" size="0.04 0.02"/>
                      <site name="attachment_site" pos="0 0.1 0" quat="-1 1 0 0"/>

                      <body name="ur_tcp_link" pos="0. 0.27 0.">
                          <geom size="0.005 0.005 0.005" pos ="0 0. 0." contype="0" conaffinity="0" type="box" rgba="0.65 0.56 0.43 1"/>
                          <joint name="ur_tcp_joint" pos="0 0 0" axis="0 1 0" limited="true" range="-3.14159 3.14159" />
                      </body>
                      <!-- Camera -->
                      <body name="camera_mount" pos="0 0 0.">
                          <geom pos="0 0.09 0" quat="0.000796327 1 0 0" type="mesh" contype="0" conaffinity="0" group="1" rgba="0.7 0.7 0.7 1" mesh="mount" />
                          <!-- mounted gear -->
                          <geom pos="0 0.09 -0.0870397" quat="0. 0.70767 0 0.70767" type="mesh" contype="0" conaffinity="1" group="1" rgba="0.8 0.8 0.8 0.8" mesh="d435" />
                          <!-- Gripper -->
                          <body name="ur_rg2_gripper_base_link" pos="0 0.08 0" quat="0. 0 0.70682518 0.70738827">
                              <inertial pos="-0.000118835633453291 4.70054905894546E-06 0.0572680906518555"  quat="0.707058 0.00723369 0.00723345 0.707081" mass="0.199035856566616" diaginertia="0.000170600248402307 0.000213152093040191 5.59878626220752E-05" />
                              <geom type="mesh" contype="0" conaffinity="1" rgba="0.5 0.5 0.5 1" friction="0.8 0.8 0.8" mesh="ur_rg2_gripper_base_link" />
                              <!-- Camera -->
                              <camera name="egocentric" pos="0 -0.09 0.01" xyaxes="1 0 0 0 -1 0" fovy="80"/>

                              <body name="rg2_gripper_finger1_finger_link" pos="0.0169 0.0103 0.105" quat="0 0 0 1">
                                  <inertial pos="0.0170975 -3.93809e-10 0.0224918"   quat="0.947655 0 -0.319297 0" mass="0.0110931" diaginertia="5.59353e-06 3.96549e-06 1.88108e-06" />
                                  <geom type="mesh" contype="0" conaffinity="1" rgba="0.5 0.5 0.5 1" friction="0.8 0.8 0.8" mesh="rg2_gripper_finger1_finger_link" />
                                  <joint name="gripper_finger1_joint" class="GRIPPER" pos="0. 0. 0." axis="0 1 0" limited="true" range="-1 0" />
                              </body>
                              
                              <body name="rg2_gripper_finger1_inner_knuckle_link" pos="0.0074 0.01 0.1215" quat="0 0 0 1">
                                  <inertial pos="0.00602756 0 0.00669926"  quat="0.699065 0.106339 0.106339 0.699065" mass="0.00724255" diaginertia="1.70064e-06 1.58577e-06 3.69621e-07" />
                                  <geom type="mesh" contype="0" conaffinity="1" rgba="0.5 0.5 0.5 1" friction="0.8 0.8 0.8" mesh="rg2_gripper_finger1_inner_knuckle_link" />
                                  <joint name="gripper_finger1_inner_knuckle_joint" class="GRIPPER" pos="0. 0. 0." axis="0 1 0" limited="true" range="-1 0" />

                                  <body name="rg2_gripper_finger1_finger_tip_link" pos="-0.0009 0.01449 0.055" quat="0 0 0 1">
                                      <inertial pos="0.0168606 3.93808e-10 0.02267"  quat="0.949317 0 -0.314322 0" mass="0.0110931" diaginertia="5.59353e-06 3.96549e-06 1.88108e-06" />
                                      <geom type="mesh" contype="1" conaffinity="1" rgba="0.5 0.5 0.5 1" friction="0.8 0.8 0.8" mesh="rg2_gripper_finger1_finger_tip_link" />
                                      <joint name="gripper_finger1_finger_tip_joint" class="GRIPPER" pos="0. 0. 0." axis="0 1 0" limited="true" range="-1 1" />
                                  </body>
                              </body>

                              <body name="rg2_gripper_finger2_finger_link" pos="-0.0171 0.0103 0.105" quat="0 0 0 1">
                                  <inertial pos="0.0170975 -3.93809e-10 0.0224918"   quat="0.947655 0 -0.319297 0" mass="0.0110931" diaginertia="5.59353e-06 3.96549e-06 1.88108e-06" />
                                  <geom type="mesh" contype="0" conaffinity="1" rgba="0.5 0.5 0.5 1" friction="0.8 0.8 0.8" mesh="rg2_gripper_finger2_finger_link" />
                                  <joint name="gripper_finger2_joint" class="GRIPPER" pos="0. 0. 0." axis="0 1 0" limited="true" range="0 1" />
                              </body>

                              <body name="rg2_gripper_finger2_inner_knuckle_link" pos="-0.0076 0.01 0.1215" quat="0 0 0 1">
                                  <inertial pos="0.00602756 0 0.00669926"  quat="0.699065 0.106339 0.106339 0.699065" mass="0.00724255" diaginertia="1.70064e-06 1.58577e-06 3.69621e-07" />
                                  <geom type="mesh" contype="0" conaffinity="1" rgba="0.5 0.5 0.5 1" friction="0.8 0.8 0.8" mesh="rg2_gripper_finger2_inner_knuckle_link" />
                                  <joint name="gripper_finger2_inner_knuckle_joint" class="GRIPPER" pos="0. 0. 0." axis="0 1 0" limited="true" range="0 1" />
              
                                  <body name="rg2_gripper_finger2_finger_tip_link" pos="0.00084055833321731 0.01449 0.055" quat="0 0 0 1">
                                      <inertial pos="0.0168606 3.93808e-10 0.02267"  quat="0.949317 0 -0.314322 0" mass="0.0110931" diaginertia="5.59353e-06 3.96549e-06 1.88108e-06" />
                                      <geom type="mesh" contype="1" conaffinity="1" rgba="0.5 0.5 0.5 1" friction="0.8 0.8 0.8" mesh="rg2_gripper_finger2_finger_tip_link" />
                                      <joint name="gripper_finger2_finger_tip_joint" class="GRIPPER" pos="0. 0. 0." axis="0 1 0" limited="true" range="-1 1" />
                                  </body>
                              </body>
                          </body>
                      </body>
                    </body>
                  </body>
                </body>
              </body>
            </body>
          </body>
        </body>
      </body>
  </worldbody>

  <equality>
      <joint joint1="gripper_finger1_joint" joint2="gripper_finger1_inner_knuckle_joint" polycoef="0 1.1 0 0 0"/>
      <joint joint1="gripper_finger1_joint" joint2="gripper_finger1_finger_tip_joint"/>
      <joint joint1="gripper_finger2_joint" joint2="gripper_finger2_inner_knuckle_joint" polycoef="0 1.1 0 0 0"/>
      <joint joint1="gripper_finger2_joint" joint2="gripper_finger2_finger_tip_joint"/>
      <joint joint1="gripper_finger1_finger_tip_joint" joint2="gripper_finger2_finger_tip_joint" polycoef="0 -1 0 0 0"/>
  </equality>

  <contact>
      <exclude body1="rg2_gripper_finger1_finger_link" body2="rg2_gripper_finger1_inner_knuckle_link"/>
      <exclude body1="rg2_gripper_finger2_finger_link" body2="rg2_gripper_finger2_inner_knuckle_link"/>

      <exclude body1="rg2_gripper_finger1_finger_link" body2="rg2_gripper_finger1_finger_tip_link"/>
      <exclude body1="rg2_gripper_finger2_finger_link" body2="rg2_gripper_finger2_finger_tip_link"/>

      <exclude body1="rg2_gripper_finger1_inner_knuckle_link" body2="rg2_gripper_finger1_finger_tip_link"/>
      <exclude body1="rg2_gripper_finger2_inner_knuckle_link" body2="rg2_gripper_finger2_finger_tip_link"/>
  </contact>
  
  <actuator>
    <position name='shoulder_pan' ctrllimited="true" ctrlrange="-3.14159 3.14159" joint='shoulder_pan_joint' kp="500" />
    <position name='shoulder_lift' ctrllimited="true" ctrlrange="-3.14159 3.14159" joint='shoulder_lift_joint' kp="500"/>
    <position name='forearm' ctrllimited="true" ctrlrange="-3.14159 3.14159" joint='elbow_joint' kp="500"/>
    <position name='wrist_1' ctrllimited="true" ctrlrange="-3.14159 3.14159" joint='wrist_1_joint' kp="100"/>
    <position name='wrist_2' ctrllimited="true" ctrlrange="-3.14159 3.14159" joint='wrist_2_joint' kp="100"/>
    <position name='wrist_3' ctrllimited="true" ctrlrange="-3.14159 3.14159" joint='wrist_3_joint' kp="100"/>
    <position name='gripper' ctrllimited="true" ctrlrange="0 1" joint='gripper_finger2_joint' kp="100"/>
 </actuator>

  <!-- <keyframe>
    <key name="home" qpos="-1.5708 -1.5708 1.5708 -1.5708 -1.5708 0"
        ctrl="-1.5708 -1.5708 1.5708 -1.5708 -1.5708 0"/>
  </keyframe> -->
</mujoco>
