<mujocoinclude>
    <worldbody>

        <body name="box_link" pos="0 0 0.395">
            <!-- Robot base table -->
            <geom size=".36 .36 .395" pos ="0 0 0" type="box" material="bench_mat2"/>
            <inertial pos="0 0 0" mass="1000" diaginertia="0 0 0" />
            <body name="ur_base_link" pos="0.18 0 0.395">

                <geom type="mesh" contype="0" conaffinity="0" group="1" rgba="0.7 0.7 0.7 1" mesh="base" />
                <geom type="mesh" rgba="0.7 0.7 0.7 1" mesh="base" />
                <body name="ur_shoulder_link" pos="0 0 0.089159">
                    <inertial pos="0 0 0" mass="3.7" diaginertia="0.0102675 0.0102675 0.00666" />
                    <joint name="ur_shoulder_pan_joint" class="UR5" pos="0 0 0" axis="0 0 1" limited="true" range="-3.14159 3.14159" />
                    <geom type="mesh" contype="0" conaffinity="0" group="1" rgba="0.7 0.7 0.7 1" mesh="shoulder" />
                    <geom type="mesh" rgba="0.7 0.7 0.7 1" mesh="shoulder" />
                    <body name="ur_upper_arm_link" pos="0 0.13585 0" quat="0.707107 0 0.707107 0">
                        <inertial pos="0 0 0.28" mass="8.393" diaginertia="0.226891 0.226891 0.0151074" />
                        <joint name="ur_shoulder_lift_joint" class="UR5" pos="0 0 0" axis="0 1 0" limited="true" range="-3.14159 0" />
                        <geom type="mesh" contype="0" conaffinity="0" group="1" rgba="0.7 0.7 0.7 1" mesh="upperarm" />
                        <geom type="mesh" rgba="0.7 0.7 0.7 1" mesh="upperarm" />
                        <body name="ur_forearm_link" pos="0 -0.1197 0.425">
                            <inertial pos="0 0 0.196" mass="2.275" diaginertia="0.0311796 0.0311796 0.004095" />
                            <joint name="ur_elbow_joint" class="UR5" pos="0 0 0" axis="0 1 0" limited="true" range="-3.14159 3.14159" />
                            <geom type="mesh" contype="0" conaffinity="0" group="1" rgba="0.7 0.7 0.7 1" mesh="forearm" />
                            <geom type="mesh" rgba="0.7 0.7 0.7 1" mesh="forearm" />
                            <body name="ur_wrist_1_link" pos="0 0 0.39225" quat="0.707107 0 0.707107 0">
                                <inertial pos="0 0.127 0" mass="1.219" diaginertia="0.0025599 0.0025599 0.0021942" />
                                <joint name="ur_wrist_1_joint" class="UR5e" pos="0 0 0" axis="0 1 0" limited="true" range="-3.14159 3.14159" />
                                <geom type="mesh" contype="0" conaffinity="0" group="1" rgba="0.7 0.7 0.7 1" mesh="wrist1" />
                                <geom type="mesh" rgba="0.7 0.7 0.7 1" mesh="wrist1" />
                                <body name="ur_wrist_2_link" pos="0 0.093 0">
                                    <inertial pos="0 0 0.1" mass="1.219" diaginertia="0.0025599 0.0025599 0.0021942" />
                                    <joint name="ur_wrist_2_joint" class="UR5e" pos="0 0 0" axis="0 0 1" limited="true" range="-3.14159 3.14159" />
                                    <geom type="mesh" contype="0" conaffinity="0" group="1" rgba="0.7 0.7 0.7 1" mesh="wrist2" />
                                    <geom type="mesh" rgba="0.7 0.7 0.7 1" mesh="wrist2" />
                                    <body name="ur_wrist_3_link" pos="0 0 0.09465">
                                        <inertial pos="0 0 0" quat="0.5 0.5 -0.5 0.5" mass="0.972908" diaginertia="0.00734082 0.00627103 0.00143257" />
                                        <joint name="ur_wrist_3_joint" class="UR5e" pos="0 0 0" axis="0 1 0" limited="true" range="-3.14159 3.14159" />
                                        <geom type="mesh" contype="0" conaffinity="0" group="1" rgba="0.7 0.7 0.7 1" mesh="wrist3" />
                                        <geom type="mesh" rgba="0.7 0.7 0.7 1" mesh="wrist3" />

                                        <body name="ur_tcp_link" pos="0. 0.27 0.">
                                            <geom size="0.01 0.01 0.01" pos ="0 0. 0." contype="0" conaffinity="0" type="box" rgba="0.65 0.56 0.43 1"/>
                                            <joint name="ur_tcp_joint" pos="0 0 0" axis="0 1 0" limited="true" range="-3.14159 3.14159" />
                                        </body>



                                        <!-- Camera -->
                                        <body name="camera_mount" pos="0 0 0.">
                                            <geom pos="0 0.09 0" quat="0.000796327 1 0 0" type="mesh" contype="0" conaffinity="0" group="1" rgba="0.7 0.7 0.7 1" mesh="mount" />
                                            <!-- mounted gear -->
                                            <!-- <geom pos="0 0.09 0" quat="0.000796327 1 0 0" type="mesh" rgba="0.1 0.1 0.1 1" mesh="mount" /> -->
                                            <geom pos="0 0.09 -0.0870397" quat="0. 0.70767 0 0.70767" type="mesh" contype="0" conaffinity="1" group="1" rgba="0.8 0.8 0.8 0.8" mesh="d435" />
                                        
                                            <!-- Gripper -->
                                            <body name="ur_rg2_gripper_base_link" pos="0 0.08 0" quat="0. 0 0.70682518 0.70738827">
                                                <inertial pos="-0.000118835633453291 4.70054905894546E-06 0.0572680906518555"  quat="0.707058 0.00723369 0.00723345 0.707081" mass="0.199035856566616" diaginertia="0.000170600248402307 0.000213152093040191 5.59878626220752E-05" />
                                                <geom type="mesh" contype="0" conaffinity="1" rgba="0.5 0.5 0.5 1" friction="0.8 0.8 0.8" mesh="ur_rg2_gripper_base_link" />
                                                <!-- Camera -->
                                                <camera name="egocentric" pos="0 -0.09 0.01" xyaxes="1 0 0 0 -1 0" fovy="80"/>

                                                <body name="rg2_gripper_finger1_finger_link" pos="0.0169 0.0103 0.105" quat="0 0 0 1">
                                                    <inertial pos="0.0170975 -3.93809e-10 0.0224918"   quat="0.947655 0 -0.319297 0" mass="0.0110931" diaginertia="5.59353e-06 3.96549e-06 1.88108e-06" />
                                                    <geom type="mesh" contype="0" conaffinity="1" rgba="0.5 0.5 0.5 1" friction="0.8 0.8 0.8" mesh="rg2_gripper_finger1_finger_link" />
                                                    <joint name="gripper_finger1_joint" class="GRIPPER" pos="0. 0. 0." axis="0 1 0" limited="true" range="-1 0" />
                                                </body>
                                                
                                                <body name="rg2_gripper_finger1_inner_knuckle_link" pos="0.0074 0.01 0.1215" quat="0 0 0 1">
                                                    <inertial pos="0.00602756 0 0.00669926"  quat="0.699065 0.106339 0.106339 0.699065" mass="0.00724255" diaginertia="1.70064e-06 1.58577e-06 3.69621e-07" />
                                                    <geom type="mesh" contype="0" conaffinity="1" rgba="0.5 0.5 0.5 1" friction="0.8 0.8 0.8" mesh="rg2_gripper_finger1_inner_knuckle_link" />
                                                    <joint name="gripper_finger1_inner_knuckle_joint" class="GRIPPER" pos="0. 0. 0." axis="0 1 0" limited="true" range="-1 0" />

                                                    <body name="rg2_gripper_finger1_finger_tip_link" pos="-0.0009 0.01449 0.055" quat="0 0 0 1">
                                                        <inertial pos="0.0168606 3.93808e-10 0.02267"  quat="0.949317 0 -0.314322 0" mass="0.0110931" diaginertia="5.59353e-06 3.96549e-06 1.88108e-06" />
                                                        <geom type="mesh" contype="1" conaffinity="1" rgba="0.5 0.5 0.5 1" friction="0.8 0.8 0.8" mesh="rg2_gripper_finger1_finger_tip_link" />
                                                        <joint name="gripper_finger1_finger_tip_joint" class="GRIPPER" pos="0. 0. 0." axis="0 1 0" limited="true" range="-1 1" />
                                                    </body>
                                                </body>

                                                <body name="rg2_gripper_finger2_finger_link" pos="-0.0171 0.0103 0.105" quat="0 0 0 1">
                                                    <inertial pos="0.0170975 -3.93809e-10 0.0224918"   quat="0.947655 0 -0.319297 0" mass="0.0110931" diaginertia="5.59353e-06 3.96549e-06 1.88108e-06" />
                                                    <geom type="mesh" contype="0" conaffinity="1" rgba="0.5 0.5 0.5 1" friction="0.8 0.8 0.8" mesh="rg2_gripper_finger2_finger_link" />
                                                    <joint name="gripper_finger2_joint" class="GRIPPER" pos="0. 0. 0." axis="0 1 0" limited="true" range="0 1" />
                                                </body>

                                                <body name="rg2_gripper_finger2_inner_knuckle_link" pos="-0.0076 0.01 0.1215" quat="0 0 0 1">
                                                    <inertial pos="0.00602756 0 0.00669926"  quat="0.699065 0.106339 0.106339 0.699065" mass="0.00724255" diaginertia="1.70064e-06 1.58577e-06 3.69621e-07" />
                                                    <geom type="mesh" contype="0" conaffinity="1" rgba="0.5 0.5 0.5 1" friction="0.8 0.8 0.8" mesh="rg2_gripper_finger2_inner_knuckle_link" />
                                                    <joint name="gripper_finger2_inner_knuckle_joint" class="GRIPPER" pos="0. 0. 0." axis="0 1 0" limited="true" range="0 1" />
                                
                                                    <body name="rg2_gripper_finger2_finger_tip_link" pos="0.00084055833321731 0.01449 0.055" quat="0 0 0 1">
                                                        <inertial pos="0.0168606 3.93808e-10 0.02267"  quat="0.949317 0 -0.314322 0" mass="0.0110931" diaginertia="5.59353e-06 3.96549e-06 1.88108e-06" />
                                                        <geom type="mesh" contype="1" conaffinity="1" rgba="0.5 0.5 0.5 1" friction="0.8 0.8 0.8" mesh="rg2_gripper_finger2_finger_tip_link" />
                                                        <joint name="gripper_finger2_finger_tip_joint" class="GRIPPER" pos="0. 0. 0." axis="0 1 0" limited="true" range="-1 1" />
                                                    </body>
                                                </body>
                                            </body>
                                        </body>
                                    </body>
                                </body>
                            </body>
                        </body>
                    </body>
                </body>
            </body>
        </body>
            <body name="base" pos="0 0 0" quat="1.7949e-09 0 0 -1">
                <inertial pos="0 0 0" quat="1.7949e-09 0 0 -1" mass="0" diaginertia="0 0 0" />
            </body>

    </worldbody>

    <equality>
        <joint joint1="gripper_finger1_joint" joint2="gripper_finger1_inner_knuckle_joint" polycoef="0 1.1 0 0 0"/>
        <joint joint1="gripper_finger1_joint" joint2="gripper_finger1_finger_tip_joint"/>
        <joint joint1="gripper_finger2_joint" joint2="gripper_finger2_inner_knuckle_joint" polycoef="0 1.1 0 0 0"/>
        <joint joint1="gripper_finger2_joint" joint2="gripper_finger2_finger_tip_joint"/>
        <joint joint1="gripper_finger1_finger_tip_joint" joint2="gripper_finger2_finger_tip_joint" polycoef="0 -1 0 0 0"/>
    </equality>


</mujocoinclude>
